/*
Clase 6 en vídeo | 15/08/2024
Clases (continuación) y manejo de errores
https://www.youtube.com/live/8p6SLAIgwZI?si=MS9o7qIhezx9NTQX&t=902
*/

// Excepción

// Produce una excepción
let myObject
// console.log(myObject.email)

// Captura de errores

// try-catch

try {
    // Código que intenta ejecutar
    console.log(myObject.email)
    console.log("Finaliza la ejecución sin errores")
} catch {
    // Bloque de error
    console.log("Se ha producido un error")
}

// Captura del error

try {
    console.log(myObject.email)
} catch (error) {
    console.log("Se ha producido un error:", error.message)
}

// finally

try {
    console.log(myObject.email)
} catch (error) {
    console.log("Se ha producido un error:", error.message)
} finally {
    console.log("Este código se ejecuta siempre")
}

// No está soportado
// try {
//     console.log(myObject.email)
// } finally {
//     console.log("Este código se ejecuta siempre")
// }

// Lanzamiento de errores

// throw

// throw new Error("Se ha producido un error");

function sumIntegers(a, b) {
    if (typeof a !== "number" || typeof b !== "number") {
        throw new TypeError("Esta operación sólo suma números")
    }
    if (!Number.isInteger(a) || !Number.isInteger(b)) {
        throw new Error("Esta operación sólo suma números enteros")
    }
    if (a == 0 || b == 0) {
        throw new SumZeroIntegerError("Se está intentando sumar cero", a, b)
    }
    return a + b
}

try {
    console.log(sumIntegers(5, 10))
    // console.log(sumIntegers(5.5, 10))
    console.log(sumIntegers("5", 10))
    // console.log(sumIntegers(5, "10"))
    // console.log(sumIntegers("5", "10"))
} catch (error) {
    console.log("Se ha producido un error:", error.message)
}

// Capturar varios tipos de errores

try {
    // console.log(sumIntegers(5.5, 10))
    console.log(sumIntegers("5", 10))
} catch (error) {
    if (error instanceof TypeError) {
        console.log("Se ha producido un error de tipo:", error.message)
    } else if (error instanceof Error) {
        console.log("Se ha producido un error:", error.message)
    }
}

// Crear excepciones personalizadas

class SumZeroIntegerError extends Error {
    constructor(message, a, b) {
        super(message)
        this.a = a
        this.b = b
    }

    printNumbers() {
        console.log(this.a, " + ", this.b)
    }
}

try {
    console.log(sumIntegers(0, 10))
} catch (error) {
    console.log("Se ha producido un error personalizado:", error.message)
    error.printNumbers()
}